Workbook
Name Cluster_List: Lookups!$B$4:$B$18
Name Evaluator_Role_List: Lookups!$C$4:$C$12
Name High_Risk_Activity_List: Lookups!$D$4:$D$19
Name KPI_List: Lookups!$H$4:$H$18
Name Package_List: Lookups!$A$4:$A$6
Name Root_Cause_List: Lookups!$F$4:$F$14
Name Score_List: Lookups!$I$2:$I$7
Name Status_List: Lookups!$G$4:$G$7
Name Yes_No_List: Lookups!$E$4:$E$5

Sheet Instructions
A1: Saadiyat Lagoons HSE Scoring Template - Google Form Ready
A2: Use Weekly_Inspections as the response/master record after upload to Google Sheets. Users should complete only visible columns; hidden columns and dashboards update automatically.
A3: 2. Complete the visible input columns only. Hidden columns calculate automatically.
A4: 3. Score each KPI from 0 to 5. 0 = collapse of control, 5 = excellent sustained control.
A5: 4. Package and Cluster are mandatory. Contractor and responsible team auto-populate.
A6: 5. Weekly_Dashboard is for top management review. Monthly_Dashboard tracks recognition trend.
A7: 6. Gap_Analysis and CAPA_Tracker are for close-out management.

Sheet Cluster_Master
A1: Cluster Master Register
A2: Reference data used for package/cluster selection and automatic population of contractor and leadership accountability details.
A3: Package | B3: Cluster | C3: Contractor | D3: Project Director (PD) | E3: Project Manager (PM) | F3: Construction Manager (CM) | G3: HSE Manager (HSEM) | H3: Section Engineer (SE)
A4: 2 | B4: Cluster 7A | C4: TAJV | D4: Hicham Adel Narch | E4: Ghaidh Alfaour | F4: George Deeb | G4: Timur | H4: Liqat
A5: 2 | B5: Cluster 7B | C5: TAJV | D5: Hicham Adel Narch | E5: Ghaidh Alfaour | F5: George Deeb | G5: Timur | H5: Eyad
A6: 2 | B6: Cluster 8A | C6: TAJV | D6: Hicham Adel Narch | E6: Ghaidh Alfaour | F6: Mohamed Salama | G6: Timur | H6: Ahmad Adel
A7: 2 | B7: Cluster 8B | C7: TAJV | D7: Hicham Adel Narch | E7: Ghaidh Alfaour | F7: Mohamed Salama | G7: Timur | H7: Ahmad Adel
A8: 2 | B8: Cluster 8C | C8: TAJV | D8: Hicham Adel Narch | E8: Ghaidh Alfaour | F8: George Deeb | G8: Timur | H8: Ahmad Adel
A9: 2 | B9: Cluster 8D | C9: TAJV | D9: Hicham Adel Narch | E9: Ghaidh Alfaour | F9: George Deeb | G9: Timur | H9: Ahmad Adel
A10: 3 | B10: Cluster 3 | C10: INNOVO | D10: Kahtan Tikriti | E10: Aiman Abdullah | F10: Salama Al Samdy | G10: Mazen Al Atwani
A11: 3 | B11: Cluster 4 | C11: INNOVO | D11: Kahtan Tikriti | E11: Aiman Abdullah | F11: Baha Basheer | G11: Mazen Al Atwani
A12: 3 | B12: Cluster 5 | C12: INNOVO | D12: Kahtan Tikriti | E12: Michael Ghali | F12: Robair Louies | G12: Mazen Al Atwani
A13: 3 | B13: Cluster 6 | C13: INNOVO | D13: Kahtan Tikriti | E13: Michael Ghali | F13: Remon Karas | G13: Mazen Al Atwani
A14: 4 | B14: Cluster 1A | C14: TAJV | D14: Hicham Adel Narch | E14: Ghaidh Alfaour | F14: Alaa Hegab | G14: Timur Terakopov | H14: Amr Taha
A15: 4 | B15: Cluster 1B | C15: TAJV | D15: Hicham Adel Narch | E15: Ghaidh Alfaour | F15: Hossam Ali Maher | G15: Timur Terakopov | H15: Md Ramadan / Osama Said
A16: 4 | B16: Cluster 2A | C16: TAJV | D16: Hicham Adel Narch | E16: Ghaidh Alfaour | F16: Ahmed Salah Hassan Dewidar | G16: Timur Terakopov | H16: Rami Issa
A17: 4 | B17: Cluster 2B | C17: TAJV | D17: Hicham Adel Narch | E17: Ghaidh Alfaour | F17: Ahmed Salah Hassan Dewidar | G17: Timur Terakopov | H17: Rami Issa
A18: 4 | B18: Cluster 2C | C18: TAJV | D18: Hicham Adel Narch | E18: Ghaidh Alfaour | F18: Ahmed Salah Hassan Dewidar | G18: Timur Terakopov | H18: Salah Nayef

Sheet Lookups
A1: Lookup Lists | I1: Score_List
A2: Lists used for dropdowns in the Weekly_Inspections and CAPA_Tracker sheets. | I2: 0
A3: Package_List | B3: Cluster_List | C3: Evaluator_Role_List | D3: High_Risk_Activity_List | E3: Yes_No_List | F3: Root_Cause_List | G3: Status_List | H3: KPI_List | I3: 1
A4: 2 | B4: Cluster 7A | C4: Project Director | D4: Work at Height | E4: YES | F4: Leadership failure | G4: Open | H4: Work at Height Control | I4: 2
A5: 3 | B5: Cluster 7B | C5: Project Manager | D5: Edge Protection | E5: NO | F5: Poor supervision | G5: In Progress | H5: Edge Protection | I5: 3
A6: 4 | B6: Cluster 8A | C6: Construction Manager | D6: Falling Objects | F6: Poor planning | G6: Closed | H6: Falling Object Prevention | I6: 4
B7: Cluster 8B | C7: HSE Manager | D7: Excavation | F7: PTW failure | G7: On Hold | H7: Excavation Safety | I7: 5
B8: Cluster 8C | C8: Section Engineer | D8: Scaffolding | F8: Weak MSRA | H8: Scaffolding Compliance
B9: Cluster 8D | C9: QA/QC | D9: Permit to Work | F9: Poor subcontractor control | H9: PTW Implementation
B10: Cluster 3 | C10: KEO | D10: MSRA / Risk Assessment | F10: Resource constraint | H10: PTW Field Verification
B11: Cluster 4 | C11: Client | D11: Lifting Operations | F11: Inadequate competence | H11: MSRA Quality
B12: Cluster 5 | C12: Other | D12: Traffic Management | F12: Poor housekeeping culture | H12: Lifting Operations
B13: Cluster 6 | D13: Housekeeping | F13: Interface / simultaneous activity conflict | H13: Traffic & Man-Machine Interface
B14: Cluster 1A | D14: Waste Management | F14: Other | H14: Housekeeping Standard
B15: Cluster 1B | D15: Fire Readiness | H15: Waste Management
B16: Cluster 2A | D16: Electrical Safety | H16: Fire Readiness
B17: Cluster 2B | D17: Portable Power Tools | H17: Supervision & Subcontractor Control
B18: Cluster 2C | D18: Heat Stress | H18: Temporary Electrical & Tool Safety
D19: Other

Sheet KPI_Weights
A1: KPI Weights and Gate Rules
A2: Weights sum to 100%. Critical gate KPIs trigger a red flag if scored 0 or 1 in any inspection.
A3: KPI | B3: Weight | C3: Critical Gate KPI? | D3: Notes
A4: Work at Height Control | B4: 0.12 | C4: YES | D4: Primary fall prevention and work at height control
A5: Edge Protection | B5: 0.12 | C5: NO | D5: Continuity and quality of edge protection
A6: Falling Object Prevention | B6: 0.05 | C6: NO | D6: Exclusion zones, toe boards, debris/tool control
A7: Excavation Safety | B7: 0.08 | C7: YES | D7: Barricading, access, services, support, spoil setback
A8: Scaffolding Compliance | B8: 0.1 | C8: YES | D8: Tagging, inspection, full planking, access, stability
A9: PTW Implementation | B9: 0.08 | C9: YES | D9: Valid PTW, correct scope, signatories, controls
A10: PTW Field Verification | B10: 0.06 | C10: NO | D10: Physical field verification before permit approval
A11: MSRA Quality | B11: 0.03 | C11: NO | D11: Task-specific risk assessment and understanding
A12: Lifting/Precast Installation | B12: 0.1 | C12: YES | D12: Lift plan, appointed person, exclusion, rigging
A13: Traffic & Man-Machine Interface | B13: 0.06 | C13: NO | D13: Pedestrian segregation, routes, signage, reversing
A14: Housekeeping/Waste Management | B14: 0.03 | C14: NO | D14: Cleanliness, stacking, access routes, slip/trip control
A15: Welfare Arrangement | B15: 0.03 | C15: NO | D15: Segregation, storage, transfer/disposal control
... A18: Temporary Electrical & Tool Safety | B18: 0.06 | C18: NO | D18: Temporary power, RCD, condition of tools/cables
A20: Total | B20: =SUM(B4:B18) -> 1

Sheet Weekly_Inspections
A1: Weekly Inspection Entry Sheet - Google Form Ready
A2: Complete only visible fields. Use the 0-5 dropdown for each KPI. Package and Cluster auto-fill contractor leadership and the dashboard updates automatically.
A3: Inspection_ID | B3: Inspection_Date | C3: Week_No | E3: Month | F3: Package | G3: Cluster | H3: Package_Cluster_Check | I3: Contractor | J3: Project Director (PD) | K3: Project Manager (PM) | L3: Construction Manager (CM) | M3: HSE Manager (HSEM) | N3: Section Engineer (SE) | O3: Your_Name | P3: Your_Role | Q3: Area_or_Villa | R3: Workers_Observed | S3: Main_High_Risk_Activity | T3: Stop_Work | U3: Work_at_Height | V3: Edge_Protection | W3: Falling_Object_Prevention | X3: Excavation_Safety | Y3: Scaffolding_Compliance | Z3: PTW_Implementation | AA3: PTW_Field_Verification | AB3: MSRA_Quality | AC3: Lifting/Precast Installation | AD3: Traffic_Interface | AE3: Housekeeping/Waste Management | AF3: Welfare Arrangement | AG3: Fire_Readiness | AH3: Supervision_Subcontractor | AI3: Electrical_Tool_Safety | AJ3: Total_Score | AK3: Raw_Score_% | AL3: Weighted_Score_% | AM3: Critical_Red_Flag | AN3: Award_Eligible | AO3: Rating_Band | AP3: Repeat_Issue_Seen | AQ3: Likely_Root_Cause | AR3: Top_3_Gaps_Observed | AS3: Immediate_Action_Taken | AT3: Preventive_Action_Required | AU3: Positive_Observations | AV3: Action_Owner | AW3: Target_Closeout_Date | AX3: Evidence_Link_or_Photo | AY3: KPI_for_PD_Attention | AZ3: KPI_for_PM_Attention | BA3: KPI_for_CM_Attention | BB3: KPI_for_HSEM_Followup | BC3: KPI_for_SE_Supervision | BD3: Leadership_Visible_Effective | BE3: Unsafe_Work_Corrected_Immediately | BF3: Best_Improved_Cluster_this_Week | BG3: Cluster_Needing_Immediate_Intervention
A4: =IF($B4="","",TEXT($B4,"yyyymmdd")&"-"&SUBSTITUTE($G4," ","")&"-"&TEXT(COUNTIF($G$4:G4,$G4),"00")) -> 20260326-Cluster2C-01 | B4: 46107 | C4: =IF($B4="","",WEEKNUM($B4,2)) -> 13 | E4: =IF($B4="","",TEXT($B4,"yyyy-mm")) -> 2026-03 | F4: 4 | G4: Cluster 2C | H4: =IF(OR($F4="",$G4=""),"",IFERROR(IF($F4=INDEX(Cluster_Master!$A$4:$A$18,MATCH($G4,Cluster_Master!$B$4:$B$18,0)),"OK","CHECK"),"CHECK")) -> OK | I4: =IFERROR(INDEX(Cluster_Master!$C$4:$C$18,MATCH($G4,Cluster_Master!$B$4:$B$18,0)),"") -> TAJV | J4: =IFERROR(INDEX(Cluster_Master!$D$4:$D$18,MATCH($G4,Cluster_Master!$B$4:$B$18,0)),"") -> Hicham Adel Narch | K4: =IFERROR(INDEX(Cluster_Master!$E$4:$E$18,MATCH($G4,Cluster_Master!$B$4:$B$18,0)),"") -> Ghaidh Alfaour | L4: =IFERROR(INDEX(Cluster_Master!$F$4:$F$18,MATCH($G4,Cluster_Master!$B$4:$B$18,0)),"") -> Ahmed Salah Hassan Dewidar | M4: =IFERROR(INDEX(Cluster_Master!$G$4:$G$18,MATCH($G4,Cluster_Master!$B$4:$B$18,0)),"") -> Timur Terakopov | N4: =IFERROR(INDEX(Cluster_Master!$H$4:$H$18,MATCH($G4,Cluster_Master!$B$4:$B$18,0)),"") -> Salah Nayef | O4: Godwin | P4: KEO | Q4: Villa 8 to 16 | S4: Work at Height | T4: YES | U4: 2 | V4: 2 | W4: 3 | X4: 3 | Y4: 2 | Z4: 3 | AA4: 1 | AB4: 3 | AD4: 3 | AE4: 1 | AF4: 1 | AG4: 2 | AH4: 1 | AI4: 2 | AJ4: =IF(COUNTA(U4:AI4)=0,"",SUM(U4:AI4)) -> 29 | AK4: =IF(COUNTA(U4:AI4)=0,"",AJ4/75) -> 0.38666667 | AL4: =IF(COUNTA(U4:AI4)=0,"",(SUM(U4*KPI_Weights!$B$4,V4*KPI_Weights!$B$5,W4*KPI_Weights!$B$6,X4*KPI_Weights!$B$7,Y4*KPI_Weights!$B$8,Z4*KPI_Weights!$B$9,AA4*KPI_Weights!$B$10,AB4*KPI_Weights!$B$11,AC4*KPI_Weights!$B$12,AD4*KPI_Weights!$B$13,AE4*KPI_Weights!$B$14,AF4*KPI_Weights!$B$15,AG4*KPI_Weights!$B$16,AH4*KPI_Weights!$B$17,AI4*KPI_Weights!$B$18))/5) -> 0.39 | AM4: =IF(COUNTA(U4:AI4)=0,"",IF(OR(U4<=1,X4<=1,Y4<=1,Z4<=1,AC4<=1),"YES","NO")) -> YES | AN4: =IF(AK4="","",IF(AND(AM4="NO",AK4>=0.75),"YES","NO")) -> NO | AO4: =IF(AK4="","",IF(AK4<0.4,"Critical",IF(AK4<0.6,"Poor",IF(AK4<0.75,"Needs Improvement",IF(AK4<0.9,"Good","Excellent"))))) -> Critical | AP4: YES | AQ4: Leadership failure | AR4: 1. Leadership failure 2. Poor supervision 3. Poor sub-contractor control 4. PTW failure | AS4: Unsafe work practices were suspended immediately. The CM of the cluster was called but he refused to visit the location. | AT4: 1. PTW must be controlled by the main contractor. 2. Close supervision of sub-contractors by main contractor shall be ensured. 3. Non-performing subcontractors shall not be paid and shall be removed from project. 4. Non-performing construction team shall be replaced without delays | AV4: 1-3rd recommendation by the cluster CM 4th recommendation by the PD. | AW4: 46114
A5: =IF($B5="","",TEXT($B5,"yyyymmdd")&"-"&SUBSTITUTE($G5," ","")&"-"&TEXT(COUNTIF($G$4:G5,$G5),"00")) -> 20260326-Cluster8A-01 | B5: 46107 | C5: =IF($B5="","",WEEKNUM($B5,2)) -> 13 | E5: =IF($B5="","",TEXT($B5,"yyyy-mm")) -> 2026-03 | F5: 2 | G5: Cluster 8A | H5: =IF(OR($F5="",$G5=""),"",IFERROR(IF($F5=INDEX(Cluster_Master!$A$4:$A$18,MATCH($G5,Cluster_Master!$B$4:$B$18,0)),"OK","CHECK"),"CHECK")) -> OK | I5: =IFERROR(INDEX(Cluster_Master!$C$4:$C$18,MATCH($G5,Cluster_Master!$B$4:$B$18,0)),"") -> TAJV | J5: =IFERROR(INDEX(Cluster_Master!$D$4:$D$18,MATCH($G5,Cluster_Master!$B$4:$B$18,0)),"") -> Hicham Adel Narch | K5: =IFERROR(INDEX(Cluster_Master!$E$4:$E$18,MATCH($G5,Cluster_Master!$B$4:$B$18,0)),"") -> Ghaidh Alfaour | L5: =IFERROR(INDEX(Cluster_Master!$F$4:$F$18,MATCH($G5,Cluster_Master!$B$4:$B$18,0)),"") -> Mohamed Salama | M5: =IFERROR(INDEX(Cluster_Master!$G$4:$G$18,MATCH($G5,Cluster_Master!$B$4:$B$18,0)),"") -> Timur | N5: =IFERROR(INDEX(Cluster_Master!$H$4:$H$18,MATCH($G5,Cluster_Master!$B$4:$B$18,0)),"") -> Ahmad Adel | O5: Godwin | P5: KEO | Q5: General | S5: Scaffolding | T5: NO | U5: 4 | V5: 4 | W5: 4 | X5: 4 | Y5: 4 | Z5: 4 | AA5: 4 | AB5: 4 | AC5: 4 | AD5: 4 | AE5: 4 | AF5: 3 | AG5: 4 | AH5: 4 | AI5: 4 | AJ5: =IF(COUNTA(U5:AI5)=0,"",SUM(U5:AI5)) -> 59 | AK5: =IF(COUNTA(U5:AI5)=0,"",AJ5/75) -> 0.78666667 | AL5: =IF(COUNTA(U5:AI5)=0,"",(SUM(U5*KPI_Weights!$B$4,V5*KPI_Weights!$B$5,W5*KPI_Weights!$B$6,X5*KPI_Weights!$B$7,Y5*KPI_Weights!$B$8,Z5*KPI_Weights!$B$9,AA5*KPI_Weights!$B$10,AB5*KPI_Weights!$B$11,AC5*KPI_Weights!$B$12,AD5*KPI_Weights!$B$13,AE5*KPI_Weights!$B$14,AF5*KPI_Weights!$B$15,AG5*KPI_Weights!$B$16,AH5*KPI_Weights!$B$17,AI5*KPI_Weights!$B$18))/5) -> 0.794 | AM5: =IF(COUNTA(U5:AI5)=0,"",IF(OR(U5<=1,X5<=1,Y5<=1,Z5<=1,AC5<=1),"YES","NO")) -> NO | AN5: =IF(AK5="","",IF(AND(AM5="NO",AK5>=0.75),"YES","NO")) -> YES | AO5: =IF(AK5="","",IF(AK5<0.4,"Critical",IF(AK5<0.6,"Poor",IF(AK5<0.75,"Needs Improvement",IF(AK5<0.9,"Good","Excellent"))))) -> Good | AP5: NO | AQ5: Other | AR5: No significant gap observed | AS5: The team was commended for their visible leadership in driving transformation at Cluster 8A. | AT5: The Construction Manager and his team were advised to ensure that sub-contractors do not mess up with their site. The following advise was given: 1. No payment for work if site condition is below the acceptable standard. 2. Close supervision of sub-contractors by the construction team of the main contractor. 3. Housekeeping shall be maintined for all shift. 4. Provide a temporary storage area for waste for each villa. 5. PTW shall remain under the control of the main contractor. | AV5: Construction Manager of Cluster 8A HSE Manager of TAJV | AW5: 46121
A6: SIDP3-BW-KEO-ZZ-ZZ-XX-RP-HS-00158 | B6: 46115 | C6: =IF($B6="","",WEEKNUM($B6,2)) -> 14 | E6: =IF($B6="","",TEXT($B6,"yyyy-mm")) -> 2026-04 | F6: 3 | G6: Cluster 4 | H6: =IF(OR($F6="",$G6=""),"",IFERROR(IF($F6=INDEX(Cluster_Master!$A$4:$A$18,MATCH($G6,Cluster_Master!$B$4:$B$18,0)),"OK","CHECK"),"CHECK")) -> OK | I6: =IFERROR(INDEX(Cluster_Master!$C$4:$C$18,MATCH($G6,Cluster_Master!$B$4:$B$18,0)),"") -> INNOVO | J6: =IFERROR(INDEX(Cluster_Master!$D$4:$D$18,MATCH($G6,Cluster_Master!$B$4:$B$18,0)),"") -> Kahtan Tikriti | K6: =IFERROR(INDEX(Cluster_Master!$E$4:$E$18,MATCH($G6,Cluster_Master!$B$4:$B$18,0)),"") -> Aiman Abdullah | L6: =IFERROR(INDEX(Cluster_Master!$F$4:$F$18,MATCH($G6,Cluster_Master!$B$4:$B$18,0)),"") -> Baha Basheer | M6: =IFERROR(INDEX(Cluster_Master!$G$4:$G$18,MATCH($G6,Cluster_Master!$B$4:$B$18,0)),"") -> Mazen Al Atwani | N6: =IFERROR(INDEX(Cluster_Master!$H$4:$H$18,MATCH($G6,Cluster_Master!$B$4:$B$18,0)),"") -> 0 | O6: Shakir | P6: KEO | Q6: villa 65,68 | S6: Edge Protection | T6: YES | U6: 3 | V6: 3 | W6: 4 | X6: na | Y6: 4 | Z6: 3 | AA6: 3 | AB6: 4 | AC6: 3 | AD6: 4 | AE6: 2 | AF6: 4 | AG6: 4 | AH6: 3 | AI6: 3 | AJ6: =IF(COUNTA(U6:AI6)=0,"",SUM(U6:AI6)) -> 47 | AK6: =IF(COUNTA(U6:AI6)=0,"",AJ6/75) -> 0.62666667 | AL6: =IF(COUNTA(U6:AI6)=0,"",(SUM(U6*KPI_Weights!$B$4,V6*KPI_Weights!$B$5,W6*KPI_Weights!$B$6,X6*KPI_Weights!$B$7,Y6*KPI_Weights!$B$8,Z6*KPI_Weights!$B$9,AA6*KPI_Weights!$B$10,AB6*KPI_Weights!$B$11,AC6*KPI_Weights!$B$12,AD6*KPI_Weights!$B$13,AE6*KPI_Weights!$B$14,AF6*KPI_Weights!$B$15,AG6*KPI_Weights!$B$16,AH6*KPI_Weights!$B$17,AI6*KPI_Weights!$B$18))/5) -> #VALUE! | AM6: =IF(COUNTA(U6:AI6)=0,"",IF(OR(U6<=1,X6<=1,Y6<=1,Z6<=1,AC6<=1),"YES","NO")) -> NO | AN6: =IF(AK6="","",IF(AND(AM6="NO",AK6>=0.75),"YES","NO")) -> NO | AO6: =IF(AK6="","",IF(AK6<0.4,"Critical",IF(AK6<0.6,"Poor",IF(AK6<0.75,"Needs Improvement",IF(AK6<0.9,"Good","Excellent"))))) -> Needs Improvement | AP6: YES | AQ6: Poor supervision | AR6: 1. Leadership failure 2. Poor supervision 3. Poor sub-contractor control 4. PTW failure | AS6: stopped the unsafe activities , called the area engineer to the location discuss about the corrective and preventive actions | AT6: conduct coordination meetings , provide adequate facilities for waste collection | AV6: Construction Manager Cluster 04 | AW6: 46122 | AX6: uploaded on Asite
A7: SIDP3-BW-KEO-ZZ-ZZ-XX-RP-HS-00159 | B7: 46116 | C7: =IF($B7="","",WEEKNUM($B7,2)) -> 14 | E7: =IF($B7="","",TEXT($B7,"yyyy-mm")) -> 2026-04 | F7: 3 | G7: Cluster 5 | H7: =IF(OR($F7="",$G7=""),"",IFERROR(IF($F7=INDEX(Cluster_Master!$A$4:$A$18,MATCH($G7,Cluster_Master!$B$4:$B$18,0)),"OK","CHECK"),"CHECK")) -> OK | I7: =IFERROR(INDEX(Cluster_Master!$C$4:$C$18,MATCH($G7,Cluster_Master!$B$4:$B$18,0)),"") -> INNOVO | J7: =IFERROR(INDEX(Cluster_Master!$D$4:$D$18,MATCH($G7,Cluster_Master!$B$4:$B$18,0)),"") -> Kahtan Tikriti | K7: =IFERROR(INDEX(Cluster_Master!$E$4:$E$18,MATCH($G7,Cluster_Master!$B$4:$B$18,0)),"") -> Michael Ghali | L7: =IFERROR(INDEX(Cluster_Master!$F$4:$F$18,MATCH($G7,Cluster_Master!$B$4:$B$18,0)),"") -> Robair Louies | M7: =IFERROR(INDEX(Cluster_Master!$G$4:$G$18,MATCH($G7,Cluster_Master!$B$4:$B$18,0)),"") -> Mazen Al Atwani | N7: =IFERROR(INDEX(Cluster_Master!$H$4:$H$18,MATCH($G7,Cluster_Master!$B$4:$B$18,0)),"") -> 0 | O7: Shakir | P7: KEO | Q7: cluster 05B villa 276 | S7: Edge Protection | T7: NO | U7: 2 | V7: 2 | W7: 3 | X7: 3 | Y7: 4 | Z7: 4 | AA7: 3.5 | AB7: 4 | AC7: 4 | AD7: 3 | AE7: 3 | AF7: 4 | AG7: 3 | AH7: 3 | AI7: 3 | AJ7: =IF(COUNTA(U7:AI7)=0,"",SUM(U7:AI7)) -> 48.5 | AK7: =IF(COUNTA(U7:AI7)=0,"",AJ7/75) -> 0.64666667 | AL7: =IF(COUNTA(U7:AI7)=0,"",(SUM(U7*KPI_Weights!$B$4,V7*KPI_Weights!$B$5,W7*KPI_Weights!$B$6,X7*KPI_Weights!$B$7,Y7*KPI_Weights!$B$8,Z7*KPI_Weights!$B$9,AA7*KPI_Weights!$B$10,AB7*KPI_Weights!$B$11,AC7*KPI_Weights!$B$12,AD7*KPI_Weights!$B$13,AE7*KPI_Weights!$B$14,AF7*KPI_Weights!$B$15,AG7*KPI_Weights!$B$16,AH7*KPI_Weights!$B$17,AI7*KPI_Weights!$B$18))/5) -> 0.626 | AM7: =IF(COUNTA(U7:AI7)=0,"",IF(OR(U7<=1,X7<=1,Y7<=1,Z7<=1,AC7<=1),"YES","NO")) -> NO | AN7: =IF(AK7="","",IF(AND(AM7="NO",AK7>=0.75),"YES","NO")) -> NO | AO7: =IF(AK7="","",IF(AK7<0.4,"Critical",IF(AK7<0.6,"Poor",IF(AK7<0.75,"Needs Improvement",IF(AK7<0.9,"Good","Excellent"))))) -> Needs Improvement | AP7: YES | AQ7: Poor subcontractor control | AR7: 1. Leadership failure 2. Poor supervision 3. Poor sub-contractor control 4. PTW failure | AS7: stopped the unsafe activities , called the area engineer to the location discuss about the corrective and preventive actions | AT7: conduct coordination meetings , provide adequate facilities for waste collection | AV7: Construciton manager | AW7: 46121 | AX7: Upload on Asite
A8: SIDP3-BW-KEO-ZZ-ZZ-XX-RP-HS-00160 | B8: 46116 | C8: =IF($B8="","",WEEKNUM($B8,2)) -> 14 | E8: =IF($B8="","",TEXT($B8,"yyyy-mm")) -> 2026-04 | F8: 3 | G8: Cluster 6 | H8: =IF(OR($F8="",$G8=""),"",IFERROR(IF($F8=INDEX(Cluster_Master!$A$4:$A$18,MATCH($G8,Cluster_Master!$B$4:$B$18,0)),"OK","CHECK"),"CHECK")) -> OK | I8: =IFERROR(INDEX(Cluster_Master!$C$4:$C$18,MATCH($G8,Cluster_Master!$B$4:$B$18,0)),"") -> INNOVO | J8: =IFERROR(INDEX(Cluster_Master!$D$4:$D$18,MATCH($G8,Cluster_Master!$B$4:$B$18,0)),"") -> Kahtan Tikriti | K8: =IFERROR(INDEX(Cluster_Master!$E$4:$E$18,MATCH($G8,Cluster_Master!$B$4:$B$18,0)),"") -> Michael Ghali | L8: =IFERROR(INDEX(Cluster_Master!$F$4:$F$18,MATCH($G8,Cluster_Master!$B$4:$B$18,0)),"") -> Remon Karas | M8: =IFERROR(INDEX(Cluster_Master!$G$4:$G$18,MATCH($G8,Cluster_Master!$B$4:$B$18,0)),"") -> Mazen Al Atwani | N8: =IFERROR(INDEX(Cluster_Master!$H$4:$H$18,MATCH($G8,Cluster_Master!$B$4:$B$18,0)),"") -> 0 | O8: Shakir | P8: KEO | Q8: cluster 06 block 02 | S8: Edge Protection | T8: NO | U8: 4 | V8: 5 | W8: 1 | X8: 1 | Y8: 4 | Z8: 3 | AA8: 3 | AB8: 4 | AC8: 1 | AD8: 1 | AE8: 3 | AF8: 3 | AG8: 5 | AH8: 5 | AI8: 5 | AJ8: =IF(COUNTA(U8:AI8)=0,"",SUM(U8:AI8)) -> 48 | AK8: =IF(COUNTA(U8:AI8)=0,"",AJ8/75) -> 0.64 | AL8: =IF(COUNTA(U8:AI8)=0,"",(SUM(U8*KPI_Weights!$B$4,V8*KPI_Weights!$B$5,W8*KPI_Weights!$B$6,X8*KPI_Weights!$B$7,Y8*KPI_Weights!$B$8,Z8*KPI_Weights!$B$9,AA8*KPI_Weights!$B$10,AB8*KPI_Weights!$B$11,AC8*KPI_Weights!$B$12,AD8*KPI_Weights!$B$13,AE8*KPI_Weights!$B$14,AF8*KPI_Weights!$B$15,AG8*KPI_Weights!$B$16,AH8*KPI_Weights!$B$17,AI8*KPI_Weights!$B$18))/5) -> 0.638 | AM8: =IF(COUNTA(U8:AI8)=0,"",IF(OR(U8<=1,X8<=1,Y8<=1,Z8<=1,AC8<=1),"YES","NO")) -> YES | AN8: =IF(AK8="","",IF(AND(AM8="NO",AK8>=0.75),"YES","NO")) -> NO | AO8: =IF(AK8="","",IF(AK8<0.4,"Critical",IF(AK8<0.6,"Poor",IF(AK8<0.75,"Needs Improvement",IF(AK8<0.9,"Good","Excellent"))))) -> Needs Improvement | AP8: YES | AQ8: Poor supervision | AR8: 1. Leadership failure 2. Poor supervision 3. Poor sub-contractor control 4. PTW failure | AS8: stopped the unsafe activities , called the area engineer to the location discuss about the corrective and preventive actions | AT8: conduct coordination meetings , provide adequate facilities for waste collection | AV8: Construction Manager | AW8: 46123 | AX8: uploaded on Asite
A9: =IF($B9="","",TEXT($B9,"yyyymmdd")&"-"&SUBSTITUTE($G9," ","")&"-"&TEXT(COUNTIF($G$4:G9,$G9),"00")) -> 20260403-Cluster3-01 | B9: 46115 | C9: =IF($B9="","",WEEKNUM($B9,2)) -> 14 | E9: =IF($B9="","",TEXT($B9,"yyyy-mm")) -> 2026-04 | F9: 3 | G9: Cluster 3 | H9: =IF(OR($F9="",$G9=""),"",IFERROR(IF($F9=INDEX(Cluster_Master!$A$4:$A$18,MATCH($G9,Cluster_Master!$B$4:$B$18,0)),"OK","CHECK"),"CHECK")) -> OK | I9: =IFERROR(INDEX(Cluster_Master!$C$4:$C$18,MATCH($G9,Cluster_Master!$B$4:$B$18,0)),"") -> INNOVO | J9: =IFERROR(INDEX(Cluster_Master!$D$4:$D$18,MATCH($G9,Cluster_Master!$B$4:$B$18,0)),"") -> Kahtan Tikriti | K9: =IFERROR(INDEX(Cluster_Master!$E$4:$E$18,MATCH($G9,Cluster_Master!$B$4:$B$18,0)),"") -> Aiman Abdullah | L9: =IFERROR(INDEX(Cluster_Master!$F$4:$F$18,MATCH($G9,Cluster_Master!$B$4:$B$18,0)),"") -> Salama Al Samdy | M9: =IFERROR(INDEX(Cluster_Master!$G$4:$G$18,MATCH($G9,Cluster_Master!$B$4:$B$18,0)),"") -> Mazen Al Atwani | N9: =IFERROR(INDEX(Cluster_Master!$H$4:$H$18,MATCH($G9,Cluster_Master!$B$4:$B$18,0)),"") -> 0 | O9: Shinoj M | P9: KEO | Q9: villa 99-110 & 16 axis | S9: Edge Protection | T9: NO | U9: 4 | V9: 3 | W9: 3 | X9: 3 | Y9: 3 | Z9: 3 | AA9: 3 | AB9: 4 | AC9: 3 | AD9: 2 | AE9: 2 | AF9: 4 | AG9: 4 | AH9: 3 | AI9: 3 | AJ9: =IF(COUNTA(U9:AI9)=0,"",SUM(U9:AI9)) -> 47 | AK9: =IF(COUNTA(U9:AI9)=0,"",AJ9/75) -> 0.62666667 | AL9: =IF(COUNTA(U9:AI9)=0,"",(SUM(U9*KPI_Weights!$B$4,V9*KPI_Weights!$B$5,W9*KPI_Weights!$B$6,X9*KPI_Weights!$B$7,Y9*KPI_Weights!$B$8,Z9*KPI_Weights!$B$9,AA9*KPI_Weights!$B$10,AB9*KPI_Weights!$B$11,AC9*KPI_Weights!$B$12,AD9*KPI_Weights!$B$13,AE9*KPI_Weights!$B$14,AF9*KPI_Weights!$B$15,AG9*KPI_Weights!$B$16,AH9*KPI_Weights!$B$17,AI9*KPI_Weights!$B$18))/5) -> 0.628 | AM9: =IF(COUNTA(U9:AI9)=0,"",IF(OR(U9<=1,X9<=1,Y9<=1,Z9<=1,AC9<=1),"YES","NO")) -> NO | AN9: =IF(AK9="","",IF(AND(AM9="NO",AK9>=0.75),"YES","NO")) -> NO | AO9: =IF(AK9="","",IF(AK9<0.4,"Critical",IF(AK9<0.6,"Poor",IF(AK9<0.75,"Needs Improvement",IF(AK9<0.9,"Good","Excellent"))))) -> Needs Improvement | AP9: YES | AQ9: Poor planning | AR9: 1. Leadership failure 2. Poor supervision 3. Poor sub-contractor control | AS9: stopped the unsafe activities , called the area engineer to the location discuss about the corrective and preventive actions | AT9: conduct coordination meetings , provide adequate facilities for waste collection | AV9: Project engineer construction manager | AX9: Asite Reff provided
A10: SIDPW-BW-KEO-ZZ-ZZ-XX-RP-HS-00196 | B10: 46114 | C10: =IF($B10="","",WEEKNUM($B10,2)) -> 14 | E10: =IF($B10="","",TEXT($B10,"yyyy-mm")) -> 2026-04 | F10: 2 | G10: Cluster 7A | H10: =IF(OR($F10="",$G10=""),"",IFERROR(IF($F10=INDEX(Cluster_Master!$A$4:$A$18,MATCH($G10,Cluster_Master!$B$4:$B$18,0)),"OK","CHECK"),"CHECK")) -> OK | I10: =IFERROR(INDEX(Cluster_Master!$C$4:$C$18,MATCH($G10,Cluster_Master!$B$4:$B$18,0)),"") -> TAJV | J10: =IFERROR(INDEX(Cluster_Master!$D$4:$D$18,MATCH($G10,Cluster_Master!$B$4:$B$18,0)),"") -> Hicham Adel Narch | K10: =IFERROR(INDEX(Cluster_Master!$E$4:$E$18,MATCH($G10,Cluster_Master!$B$4:$B$18,0)),"") -> Ghaidh Alfaour | L10: =IFERROR(INDEX(Cluster_Master!$F$4:$F$18,MATCH($G10,Cluster_Master!$B$4:$B$18,0)),"") -> George Deeb | M10: =IFERROR(INDEX(Cluster_Master!$G$4:$G$18,MATCH($G10,Cluster_Master!$B$4:$B$18,0)),"") -> Timur | N10: =IFERROR(INDEX(Cluster_Master!$H$4:$H$18,MATCH($G10,Cluster_Master!$B$4:$B$18,0)),"") -> Liqat | O10: Jackson | P10: KEO | Q10: General | S10: Edge Protection | T10: YES | U10: 3 | V10: 3 | W10: 1 | X10: NA | Y10: 2.5 | Z10: 2 | AA10: 1 | AB10: 4 | AC10: 2 | AD10: 4 | AE10: 2 | AF10: 4 | AG10: 2 | AH10: 1 | AI10: 2 | AJ10: =IF(COUNTA(U10:AI10)=0,"",SUM(U10:AI10)) -> 33.5 | AK10: =IF(COUNTA(U10:AI10)=0,"",AJ10/75) -> 0.44666667 | AL10: =IF(COUNTA(U10:AI10)=0,"",(SUM(U10*KPI_Weights!$B$4,V10*KPI_Weights!$B$5,W10*KPI_Weights!$B$6,X10*KPI_Weights!$B$7,Y10*KPI_Weights!$B$8,Z10*KPI_Weights!$B$9,AA10*KPI_Weights!$B$10,AB10*KPI_Weights!$B$11,AC10*KPI_Weights!$B$12,AD10*KPI_Weights!$B$13,AE10*KPI_Weights!$B$14,AF10*KPI_Weights!$B$15,AG10*KPI_Weights!$B$16,AH10*KPI_Weights!$B$17,AI10*KPI_Weights!$B$18))/5) -> #VALUE! | AM10: =IF(COUNTA(U10:AI10)=0,"",IF(OR(U10<=1,X10<=1,Y10<=1,Z10<=1,AC10<=1),"YES","NO")) -> NO | AN10: =IF(AK10="","",IF(AND(AM10="NO",AK10>=0.75),"YES","NO")) -> NO | AO10: =IF(AK10="","",IF(AK10<0.4,"Critical",IF(AK10<0.6,"Poor",IF(AK10<0.75,"Needs Improvement",IF(AK10<0.9,"Good","Excellent"))))) -> Poor | AP10: YES | AQ10: Poor supervision | AR10: 1. Leadership failure 2. Poor supervision 3. Poor sub-contractor control 4. PTW failure | AS10: All activities inside the visited villa have been suspened and corrective and preventive actions required have been communicated with action owners . | AT10: Provide competent supervsion to ensure the activities inline with OSH requirements and proeprly managing the subcontractor. | AV10: Project engineer construction manager | AW10: 46121 | AX10: Asite Reff provided
A11: SIDP3-BW-KEO-ZZ-ZZ-XX-RP-HS-00161 | B11: 46118 | C11: =IF($B11="","",WEEKNUM($B11,2)) -> 15 | E11: =IF($B11="","",TEXT($B11,"yyyy-mm")) -> 2026-04 | F11: 3 | G11: Cluster 3 | H11: =IF(OR($F11="",$G11=""),"",IFERROR(IF($F11=INDEX(Cluster_Master!$A$4:$A$18,MATCH($G11,Cluster_Master!$B$4:$B$18,0)),"OK","CHECK"),"CHECK")) -> OK | I11: =IFERROR(INDEX(Cluster_Master!$C$4:$C$18,MATCH($G11,Cluster_Master!$B$4:$B$18,0)),"") -> INNOVO | J11: =IFERROR(INDEX(Cluster_Master!$D$4:$D$18,MATCH($G11,Cluster_Master!$B$4:$B$18,0)),"") -> Kahtan Tikriti | K11: =IFERROR(INDEX(Cluster_Master!$E$4:$E$18,MATCH($G11,Cluster_Master!$B$4:$B$18,0)),"") -> Aiman Abdullah | L11: =IFERROR(INDEX(Cluster_Master!$F$4:$F$18,MATCH($G11,Cluster_Master!$B$4:$B$18,0)),"") -> Salama Al Samdy | M11: =IFERROR(INDEX(Cluster_Master!$G$4:$G$18,MATCH($G11,Cluster_Master!$B$4:$B$18,0)),"") -> Mazen Al Atwani | N11: =IFERROR(INDEX(Cluster_Master!$H$4:$H$18,MATCH($G11,Cluster_Master!$B$4:$B$18,0)),"") -> 0 | O11: Shinoj M | P11: KEO | Q11: Villa 12-17 | S11: Traffic Management | T11: NO | U11: 3 | V11: 2 | W11: 3 | X11: 3 | Y11: 4 | Z11: 2 | AA11: 3 | AB11: 3 | AC11: 3 | AD11: 1 | AE11: 4 | AF11: 4 | AG11: 3 | AH11: 3 | AI11: 3 | AJ11: =IF(COUNTA(U11:AI11)=0,"",SUM(U11:AI11)) -> 44 | AK11: =IF(COUNTA(U11:AI11)=0,"",AJ11/75) -> 0.58666667 | AL11: =IF(COUNTA(U11:AI11)=0,"",(SUM(U11*KPI_Weights!$B$4,V11*KPI_Weights!$B$5,W11*KPI_Weights!$B$6,X11*KPI_Weights!$B$7,Y11*KPI_Weights!$B$8,Z11*KPI_Weights!$B$9,AA11*KPI_Weights!$B$10,AB11*KPI_Weights!$B$11,AC11*KPI_Weights!$B$12,AD11*KPI_Weights!$B$13,AE11*KPI_Weights!$B$14,AF11*KPI_Weights!$B$15,AG11*KPI_Weights!$B$16,AH11*KPI_Weights!$B$17,AI11*KPI_Weights!$B$18))/5) -> 0.568 | AM11: =IF(COUNTA(U11:AI11)=0,"",IF(OR(U11<=1,X11<=1,Y11<=1,Z11<=1,AC11<=1),"YES","NO")) -> NO | AN11: =IF(AK11="","",IF(AND(AM11="NO",AK11>=0.75),"YES","NO")) -> NO | AO11: =IF(AK11="","",IF(AK11<0.4,"Critical",IF(AK11<0.6,"Poor",IF(AK11<0.75,"Needs Improvement",IF(AK11<0.9,"Good","Excellent"))))) -> Poor | AP11: YES | AQ11: Poor planning | AR11: 1. Poor coordination 2. Poor sub-contractor control 4. PTW failure | AS11: 1. Maintain the pedestrian access 2. Reinstate the barricades 3. Provide access to the villas 4.Apoint competent scaffolding crew | AT11: 1. Preplan the activities 2. Conduct a week's look-ahead planning to avoid conflicts 3. Conduct training for the involved teams 4. Evaluate the competency of the scaffolding crew | AV11: Construction manager Project Engineer HSE officer | AX11: Asite Reff provided
A12: SIDPW-BW-KEO-ZZ-ZZ-XX-RP-HS-00197 | B12: 46114 | C12: =IF($B12="","",WEEKNUM($B12,2)) -> 14 | E12: =IF($B12="","",TEXT($B12,"yyyy-mm")) -> 2026-04 | F12: 2 | G12: Cluster 7B | H12: =IF(OR($F12="",$G12=""),"",IFERROR(IF($F12=INDEX(Cluster_Master!$A$4:$A$18,MATCH($G12,Cluster_Master!$B$4:$B$18,0)),"OK","CHECK"),"CHECK")) -> OK | I12: =IFERROR(INDEX(Cluster_Master!$C$4:$C$18,MATCH($G12,Cluster_Master!$B$4:$B$18,0)),"") -> TAJV | J12: =IFERROR(INDEX(Cluster_Master!$D$4:$D$18,MATCH($G12,Cluster_Master!$B$4:$B$18,0)),"") -> Hicham Adel Narch | K12: =IFERROR(INDEX(Cluster_Master!$E$4:$E$18,MATCH($G12,Cluster_Master!$B$4:$B$18,0)),"") -> Ghaidh Alfaour | L12: =IFERROR(INDEX(Cluster_Master!$F$4:$F$18,MATCH($G12,Cluster_Master!$B$4:$B$18,0)),"") -> George Deeb | M12: =IFERROR(INDEX(Cluster_Master!$G$4:$G$18,MATCH($G12,Cluster_Master!$B$4:$B$18,0)),"") -> Timur | N12: =IFERROR(INDEX(Cluster_Master!$H$4:$H$18,MATCH($G12,Cluster_Master!$B$4:$B$18,0)),"") -> Eyad | O12: Jackson | P12: KEO | Q12: General | S12: Work at Height | T12: NO | U12: 3.5 | V12: 3.5 | W12: 4 | X12: NA | Y12: 3.5 | Z12: 4 | AA12: 2 | AB12: 4 | AC12: 3.5 | AD12: 4.5 | AE12: 5 | AF12: 4 | AG12: 3 | AH12: 4 | AI12: 3 | AJ12: =IF(COUNTA(U12:AI12)=0,"",SUM(U12:AI12)) -> 51.5 | AK12: =IF(COUNTA(U12:AI12)=0,"",AJ12/75) -> 0.68666667 | AL12: =IF(COUNTA(U12:AI12)=0,"",(SUM(U12*KPI_Weights!$B$4,V12*KPI_Weights!$B$5,W12*KPI_Weights!$B$6,X12*KPI_Weights!$B$7,Y12*KPI_Weights!$B$8,Z12*KPI_Weights!$B$9,AA12*KPI_Weights!$B$10,AB12*KPI_Weights!$B$11,AC12*KPI_Weights!$B$12,AD12*KPI_Weights!$B$13,AE12*KPI_Weights!$B$14,AF12*KPI_Weights!$B$15,AG12*KPI_Weights!$B$16,AH12*KPI_Weights!$B$17,AI12*KPI_Weights!$B$18))/5) -> #VALUE! | AM12: =IF(COUNTA(U12:AI12)=0,"",IF(OR(U12<=1,X12<=1,Y12<=1,Z12<=1,AC12<=1),"YES","NO")) -> NO | AN12: =IF(AK12="","",IF(AND(AM12="NO",AK12>=0.75),"YES","NO")) -> NO | AO12: =IF(AK12="","",IF(AK12<0.4,"Critical",IF(AK12<0.6,"Poor",IF(AK12<0.75,"Needs Improvement",IF(AK12<0.9,"Good","Excellent"))))) -> Needs Improvement | AP12: YES | AQ12: Poor subcontractor control | AR12: 1. Poor sub-contractor control | AS12: Cordination Meeting conducted | AT12: Sub contractor shall be managed based on the project OSH Requirements | AV12: Project engineer construction manager | AW12: 46121 | AX12: Asite Reff provided
A13: SIDPW-BW-KEO-ZZ-ZZ-XX-RP-HS-00198 | B13: 46115 | C13: =IF($B13="","",WEEKNUM($B13,2)) -> 14 | E13: =IF($B13="","",TEXT($B13,"yyyy-mm")) -> 2026-04 | F13: 2 | G13: Cluster 8C | H13: =IF(OR($F13="",$G13=""),"",IFERROR(IF($F13=INDEX(Cluster_Master!$A$4:$A$18,MATCH($G13,Cluster_Master!$B$4:$B$18,0)),"OK","CHECK"),"CHECK")) -> OK | I13: =IFERROR(INDEX(Cluster_Master!$C$4:$C$18,MATCH($G13,Cluster_Master!$B$4:$B$18,0)),"") -> TAJV | J13: =IFERROR(INDEX(Cluster_Master!$D$4:$D$18,MATCH($G13,Cluster_Master!$B$4:$B$18,0)),"") -> Hicham Adel Narch | K13: =IFERROR(INDEX(Cluster_Master!$E$4:$E$18,MATCH($G13,Cluster_Master!$B$4:$B$18,0)),"") -> Ghaidh Alfaour | L13: =IFERROR(INDEX(Cluster_Master!$F$4:$F$18,MATCH($G13,Cluster_Master!$B$4:$B$18,0)),"") -> George Deeb | M13: =IFERROR(INDEX(Cluster_Master!$G$4:$G$18,MATCH($G13,Cluster_Master!$B$4:$B$18,0)),"") -> Timur | N13: =IFERROR(INDEX(Cluster_Master!$H$4:$H$18,MATCH($G13,Cluster_Master!$B$4:$B$18,0)),"") -> Ahmad Adel | O13: Jackson | P13: KEO | Q13: General | S13: Scaffolding | T13: NO | U13: 3 | V13: 3.5 | W13: 2.5 | X13: 4 | Y13: 3 | Z13: 3.5 | AA13: 3.5 | AB13: 4 | AC13: 3 | AD13: 4 | AE13: 4 | AF13: 4 | AG13: 2.5 | AH13: 3 | AI13: 3.5 | AJ13: =IF(COUNTA(U13:AI13)=0,"",SUM(U13:AI13)) -> 51 | AK13: =IF(COUNTA(U13:AI13)=0,"",AJ13/75) -> 0.68 | AL13: =IF(COUNTA(U13:AI13)=0,"",(SUM(U13*KPI_Weights!$B$4,V13*KPI_Weights!$B$5,W13*KPI_Weights!$B$6,X13*KPI_Weights!$B$7,Y13*KPI_Weights!$B$8,Z13*KPI_Weights!$B$9,AA13*KPI_Weights!$B$10,AB13*KPI_Weights!$B$11,AC13*KPI_Weights!$B$12,AD13*KPI_Weights!$B$13,AE13*KPI_Weights!$B$14,AF13*KPI_Weights!$B$15,AG13*KPI_Weights!$B$16,AH13*KPI_Weights!$B$17,AI13*KPI_Weights!$B$18))/5) -> 0.668 | AM13: =IF(COUNTA(U13:AI13)=0,"",IF(OR(U13<=1,X13<=1,Y13<=1,Z13<=1,AC13<=1),"YES","NO")) -> NO | AN13: =IF(AK13="","",IF(AND(AM13="NO",AK13>=0.75),"YES","NO")) -> NO | AO13: =IF(AK13="","",IF(AK13<0.4,"Critical",IF(AK13<0.6,"Poor",IF(AK13<0.75,"Needs Improvement",IF(AK13<0.9,"Good","Excellent"))))) -> Needs Improvement | AP13: YES | AQ13: Inadequate competence | AR13: Inadequate comptence | AS13: Coordination Meeting conducted | AT13: Regular Training sessions shall be carried out | AW13: 46122 | AX13: Asite Reff provided
A14: SIDPW-BW-KEO-ZZ-ZZ-XX-RP-HS-00198 | B14: 46115 | C14: =IF($B14="","",WEEKNUM($B14,2)) -> 14 | E14: =IF($B14="","",TEXT($B14,"yyyy-mm")) -> 2026-04 | F14: 2 | G14: Cluster 8D | H14: =IF(OR($F14="",$G14=""),"",IFERROR(IF($F14=INDEX(Cluster_Master!$A$4:$A$18,MATCH($G14,Cluster_Master!$B$4:$B$18,0)),"OK","CHECK"),"CHECK")) -> OK | I14: =IFERROR(INDEX(Cluster_Master!$C$4:$C$18,MATCH($G14,Cluster_Master!$B$4:$B$18,0)),"") -> TAJV | J14: =IFERROR(INDEX(Cluster_Master!$D$4:$D$18,MATCH($G14,Cluster_Master!$B$4:$B$18,0)),"") -> Hicham Adel Narch | K14: =IFERROR(INDEX(Cluster_Master!$E$4:$E$18,MATCH($G14,Cluster_Master!$B$4:$B$18,0)),"") -> Ghaidh Alfaour | L14: =IFERROR(INDEX(Cluster_Master!$F$4:$F$18,MATCH($G14,Cluster_Master!$B$4:$B$18,0)),"") -> George Deeb | M14: =IFERROR(INDEX(Cluster_Master!$G$4:$G$18,MATCH($G14,Cluster_Master!$B$4:$B$18,0)),"") -> Timur | N14: =IFERROR(INDEX(Cluster_Master!$H$4:$H$18,MATCH($G14,Cluster_Master!$B$4:$B$18,0)),"") -> Ahmad Adel | O14: Jackson | P14: KEO | Q14: General | S14: Electrical Safety | T14: NO | U14: 3.5 | V14: 3 | W14: 3 | X14: 4 | Y14: 3.5 | Z14: 3 | AA14: 3 | AB14: 4 | AC14: 3 | AD14: 4 | AE14: 3.5 | AF14: 4 | AG14: 3 | AH14: 3 | AI14: 3.5 | AJ14: =IF(COUNTA(U14:AI14)=0,"",SUM(U14:AI14)) -> 51 | AK14: =IF(COUNTA(U14:AI14)=0,"",AJ14/75) -> 0.68 | AL14: =IF(COUNTA(U14:AI14)=0,"",(SUM(U14*KPI_Weights!$B$4,V14*KPI_Weights!$B$5,W14*KPI_Weights!$B$6,X14*KPI_Weights!$B$7,Y14*KPI_Weights!$B$8,Z14*KPI_Weights!$B$9,AA14*KPI_Weights!$B$10,AB14*KPI_Weights!$B$11,AC14*KPI_Weights!$B$12,AD14*KPI_Weights!$B$13,AE14*KPI_Weights!$B$14,AF14*KPI_Weights!$B$15,AG14*KPI_Weights!$B$16,AH14*KPI_Weights!$B$17,AI14*KPI_Weights!$B$18))/5) -> 0.671 | AM14: =IF(COUNTA(U14:AI14)=0,"",IF(OR(U14<=1,X14<=1,Y14<=1,Z14<=1,AC14<=1),"YES","NO")) -> NO | AN14: =IF(AK14="","",IF(AND(AM14="NO",AK14>=0.75),"YES","NO")) -> NO | AO14: =IF(AK14="","",IF(AK14<0.4,"Critical",IF(AK14<0.6,"Poor",IF(AK14<0.75,"Needs Improvement",IF(AK14<0.9,"Good","Excellent"))))) -> Needs Improvement | AP14: YES | AQ14: Poor supervision | AR14: Poor supervision | AS14: Coordination Meeting conducted | AT14: Regular scaffolding and Distribution Board inspection | AW14: 46122 | AX14: Asite Reff provided
A15: SIDPW-BW-KEO-ZZ-ZZ-XX-RP-HS-00199 | B15: 46118 | C15: =IF($B15="","",WEEKNUM($B15,2)) -> 15 | E15: =IF($B15="","",TEXT($B15,"yyyy-mm")) -> 2026-04 | F15: 4 | G15: Cluster 1A | H15: =IF(OR($F15="",$G15=""),"",IFERROR(IF($F15=INDEX(Cluster_Master!$A$4:$A$18,MATCH($G15,Cluster_Master!$B$4:$B$18,0)),"OK","CHECK"),"CHECK")) -> OK | I15: =IFERROR(INDEX(Cluster_Master!$C$4:$C$18,MATCH($G15,Cluster_Master!$B$4:$B$18,0)),"") -> TAJV | J15: =IFERROR(INDEX(Cluster_Master!$D$4:$D$18,MATCH($G15,Cluster_Master!$B$4:$B$18,0)),"") -> Hicham Adel Narch | K15: =IFERROR(INDEX(Cluster_Master!$E$4:$E$18,MATCH($G15,Cluster_Master!$B$4:$B$18,0)),"") -> Ghaidh Alfaour | L15: =IFERROR(INDEX(Cluster_Master!$F$4:$F$18,MATCH($G15,Cluster_Master!$B$4:$B$18,0)),"") -> Alaa Hegab | M15: =IFERROR(INDEX(Cluster_Master!$G$4:$G$18,MATCH($G15,Cluster_Master!$B$4:$B$18,0)),"") -> Timur Terakopov | N15: =IFERROR(INDEX(Cluster_Master!$H$4:$H$18,MATCH($G15,Cluster_Master!$B$4:$B$18,0)),"") -> Amr Taha | O15: Jackson | P15: KEO | Q15: General | S15: Scaffolding | T15: YES | U15: 3 | V15: 4 | W15: 4 | X15: 3 | Y15: 2.5 | Z15: 4 | AA15: 4 | AB15: 4 | AC15: 3 | AD15: 4 | AE15: 4 | AF15: 3.5 | AG15: 3.5 | AH15: 2.5 | AI15: 3.5 | AJ15: =IF(COUNTA(U15:AI15)=0,"",SUM(U15:AI15)) -> 52.5 | AK15: =IF(COUNTA(U15:AI15)=0,"",AJ15/75) -> 0.7 | AL15: =IF(COUNTA(U15:AI15)=0,"",(SUM(U15*KPI_Weights!$B$4,V15*KPI_Weights!$B$5,W15*KPI_Weights!$B$6,X15*KPI_Weights!$B$7,Y15*KPI_Weights!$B$8,Z15*KPI_Weights!$B$9,AA15*KPI_Weights!$B$10,AB15*KPI_Weights!$B$11,AC15*KPI_Weights!$B$12,AD15*KPI_Weights!$B$13,AE15*KPI_Weights!$B$14,AF15*KPI_Weights!$B$15,AG15*KPI_Weights!$B$16,AH15*KPI_Weights!$B$17,AI15*KPI_Weights!$B$18))/5) -> 0.687 | AM15: =IF(COUNTA(U15:AI15)=0,"",IF(OR(U15<=1,X15<=1,Y15<=1,Z15<=1,AC15<=1),"YES","NO")) -> NO | AN15: =IF(AK15="","",IF(AND(AM15="NO",AK15>=0.75),"YES","NO")) -> NO | AO15: =IF(AK15="","",IF(AK15<0.4,"Critical",IF(AK15<0.6,"Poor",IF(AK15<0.75,"Needs Improvement",IF(AK15<0.9,"Good","Excellent"))))) -> Needs Improvement | AP15: YES | AQ15: Poor subcontractor control | AR15: Poor subcontractor control | AS15: Unsafe work has been suspended | AT15: Regular scaffolding and Distribution Board inspection | AW15: 46124 | AX15: Asite Reff provided
A16: SIDPW-BW-KEO-ZZ-ZZ-XX-RP-HS-00200 | B16: 46118 | C16: =IF($B16="","",WEEKNUM($B16,2)) -> 15 | E16: =IF($B16="","",TEXT($B16,"yyyy-mm")) -> 2026-04 | F16: 4 | G16: Cluster 1B | H16: =IF(OR($F16="",$G16=""),"",IFERROR(IF($F16=INDEX(Cluster_Master!$A$4:$A$18,MATCH($G16,Cluster_Master!$B$4:$B$18,0)),"OK","CHECK"),"CHECK")) -> OK | I16: =IFERROR(INDEX(Cluster_Master!$C$4:$C$18,MATCH($G16,Cluster_Master!$B$4:$B$18,0)),"") -> TAJV | J16: =IFERROR(INDEX(Cluster_Master!$D$4:$D$18,MATCH($G16,Cluster_Master!$B$4:$B$18,0)),"") -> Hicham Adel Narch | K16: =IFERROR(INDEX(Cluster_Master!$E$4:$E$18,MATCH($G16,Cluster_Master!$B$4:$B$18,0)),"") -> Ghaidh Alfaour | L16: =IFERROR(INDEX(Cluster_Master!$F$4:$F$18,MATCH($G16,Cluster_Master!$B$4:$B$18,0)),"") -> Hossam Ali Maher | M16: =IFERROR(INDEX(Cluster_Master!$G$4:$G$18,MATCH($G16,Cluster_Master!$B$4:$B$18,0)),"") -> Timur Terakopov | N16: =IFERROR(INDEX(Cluster_Master!$H$4:$H$18,MATCH($G16,Cluster_Master!$B$4:$B$18,0)),"") -> Md Ramadan / Osama Said | O16: Abdel Monem | P16: KEO | Q16: General | S16: Scaffolding | T16: NO | U16: 4 | V16: 4 | W16: 4.5 | X16: 4 | Y16: 4 | Z16: 4 | AA16: 4 | AB16: 4 | AC16: 4 | AD16: 4 | AE16: 4 | AF16: 4 | AG16: 3.5 | AH16: 3.5 | AI16: 3 | AJ16: =IF(COUNTA(U16:AI16)=0,"",SUM(U16:AI16)) -> 58.5 | AK16: =IF(COUNTA(U16:AI16)=0,"",AJ16/75) -> 0.78 | AL16: =IF(COUNTA(U16:AI16)=0,"",(SUM(U16*KPI_Weights!$B$4,V16*KPI_Weights!$B$5,W16*KPI_Weights!$B$6,X16*KPI_Weights!$B$7,Y16*KPI_Weights!$B$8,Z16*KPI_Weights!$B$9,AA16*KPI_Weights!$B$10,AB16*KPI_Weights!$B$11,AC16*KPI_Weights!$B$12,AD16*KPI_Weights!$B$13,AE16*KPI_Weights!$B$14,AF16*KPI_Weights!$B$15,AG16*KPI_Weights!$B$16,AH16*KPI_Weights!$B$17,AI16*KPI_Weights!$B$18))/5) -> 0.785 | AM16: =IF(COUNTA(U16:AI16)=0,"",IF(OR(U16<=1,X16<=1,Y16<=1,Z16<=1,AC16<=1),"YES","NO")) -> NO | AN16: =IF(AK16="","",IF(AND(AM16="NO",AK16>=0.75),"YES","NO")) -> YES | AO16: =IF(AK16="","",IF(AK16<0.4,"Critical",IF(AK16<0.6,"Poor",IF(AK16<0.75,"Needs Improvement",IF(AK16<0.9,"Good","Excellent"))))) -> Good | AP16: YES | AQ16: Poor subcontractor control | AR16: Poor subcontractor control | AS16: Coordination Meeting conducted | AT16: Regular scaffolding and Distribution Board inspection | AW16: 46124 | AX16: Asite Reff provided
A17: SIDP3-BW-KEO-ZZ-ZZ-XX-RP-HS-00162 | B17: 46118 | C17: =IF($B17="","",WEEKNUM($B17,2)) -> 15 | E17: =IF($B17="","",TEXT($B17,"yyyy-mm")) -> 2026-04 | F17: 3 | G17: Cluster 4 | H17: =IF(OR($F17="",$G17=""),"",IFERROR(IF($F17=INDEX(Cluster_Master!$A$4:$A$18,MATCH($G17,Cluster_Master!$B$4:$B$18,0)),"OK","CHECK"),"CHECK")) -> OK | I17: =IFERROR(INDEX(Cluster_Master!$C$4:$C$18,MATCH($G17,Cluster_Master!$B$4:$B$18,0)),"") -> INNOVO | J17: =IFERROR(INDEX(Cluster_Master!$D$4:$D$18,MATCH($G17,Cluster_Master!$B$4:$B$18,0)),"") -> Kahtan Tikriti | K17: =IFERROR(INDEX(Cluster_Master!$E$4:$E$18,MATCH($G17,Cluster_Master!$B$4:$B$18,0)),"") -> Aiman Abdullah | L17: =IFERROR(INDEX(Cluster_Master!$F$4:$F$18,MATCH($G17,Cluster_Master!$B$4:$B$18,0)),"") -> Baha Basheer | M17: =IFERROR(INDEX(Cluster_Master!$G$4:$G$18,MATCH($G17,Cluster_Master!$B$4:$B$18,0)),"") -> Mazen Al Atwani | N17: =IFERROR(INDEX(Cluster_Master!$H$4:$H$18,MATCH($G17,Cluster_Master!$B$4:$B$18,0)),"") -> 0 | O17: Shakir | P17: KEO | Q17: General | S17: Lifting Operations | T17: YES | U17: 4 | V17: 4 | W17: 4 | X17: 3 | Y17: 3 | Z17: 2 | AA17: 1 | AB17: 4 | AC17: 3 | AD17: 3 | AE17: 3 | AF17: 4 | AG17: 2 | AH17: 2 | AI17: 3 | AJ17: =IF(COUNTA(U17:AI17)=0,"",SUM(U17:AI17)) -> 45 | AK17: =IF(COUNTA(U17:AI17)=0,"",AJ17/75) -> 0.6 | AL17: =IF(COUNTA(U17:AI17)=0,"",(SUM(U17*KPI_Weights!$B$4,V17*KPI_Weights!$B$5,W17*KPI_Weights!$B$6,X17*KPI_Weights!$B$7,Y17*KPI_Weights!$B$8,Z17*KPI_Weights!$B$9,AA17*KPI_Weights!$B$10,AB17*KPI_Weights!$B$11,AC17*KPI_Weights!$B$12,AD17*KPI_Weights!$B$13,AE17*KPI_Weights!$B$14,AF17*KPI_Weights!$B$15,AG17*KPI_Weights!$B$16,AH17*KPI_Weights!$B$17,AI17*KPI_Weights!$B$18))/5) -> 0.614 | AM17: =IF(COUNTA(U17:AI17)=0,"",IF(OR(U17<=1,X17<=1,Y17<=1,Z17<=1,AC17<=1),"YES","NO")) -> NO | AN17: =IF(AK17="","",IF(AND(AM17="NO",AK17>=0.75),"YES","NO")) -> NO | AO17: =IF(AK17="","",IF(AK17<0.4,"Critical",IF(AK17<0.6,"Poor",IF(AK17<0.75,"Needs Improvement",IF(AK17<0.9,"Good","Excellent"))))) -> Needs Improvement | AP17: YES | AQ17: Poor supervision | AR17: • HSE Management System Implementation • Planning and Control • Inspection, Monitoring, and Compliance | AS17: • Unsafe activities were stopped immediately. • Housekeeping, waste removal, and access rectification started | AT17: Enforce strict supervision and permit compliance. Implement proper planning, housekeeping, and waste management systems. Conduct regular inspections, training, and safety awareness programs. | AV17: Construction manager Project Engineer | AW17: 46122 | AX17: Asite Reff provided
A18: SIDP3-BW-KEO-ZZ-ZZ-XX-WR-HS-75 | B18: 46119 | C18: =IF($B18="","",WEEKNUM($B18,2)) -> 15 | E18: =IF($B18="","",TEXT($B18,"yyyy-mm")) -> 2026-04 | F18: 3 | G18: Cluster 5 | H18: =IF(OR($F18="",$G18=""),"",IFERROR(IF($F18=INDEX(Cluster_Master!$A$4:$A$18,MATCH($G18,Cluster_Master!$B$4:$B$18,0)),"OK","CHECK"),"CHECK")) -> OK | I18: =IFERROR(INDEX(Cluster_Master!$C$4:$C$18,MATCH($G18,Cluster_Master!$B$4:$B$18,0)),"") -> INNOVO | J18: =IFERROR(INDEX(Cluster_Master!$D$4:$D$18,MATCH($G18,Cluster_Master!$B$4:$B$18,0)),"") -> Kahtan Tikriti | K18: =IFERROR(INDEX(Cluster_Master!$E$4:$E$18,MATCH($G18,Cluster_Master!$B$4:$B$18,0)),"") -> Michael Ghali | L18: =IFERROR(INDEX(Cluster_Master!$F$4:$F$18,MATCH($G18,Cluster_Master!$B$4:$B$18,0)),"") -> Robair Louies | M18: =IFERROR(INDEX(Cluster_Master!$G$4:$G$18,MATCH($G18,Cluster_Master!$B$4:$B$18,0)),"") -> Mazen Al Atwani | N18: =IFERROR(INDEX(Cluster_Master!$H$4:$H$18,MATCH($G18,Cluster_Master!$B$4:$B$18,0)),"") -> 0 | O18: Shakir | P18: KEO | Q18: General | S18: Fire Readiness | T18: NO | U18: 4 | V18: 4 | W18: 3 | X18: 3 | Y18: 4 | Z18: 4 | AA18: 3 | AB18: 3 | AC18: 4 | AD18: 3 | AE18: 2 | AF18: 4 | AG18: 3 | AH18: 4 | AI18: 2 | AJ18: =IF(COUNTA(U18:AI18)=0,"",SUM(U18:AI18)) -> 50 | AK18: =IF(COUNTA(U18:AI18)=0,"",AJ18/75) -> 0.66666667 | AL18: =IF(COUNTA(U18:AI18)=0,"",(SUM(U18*KPI_Weights!$B$4,V18*KPI_Weights!$B$5,W18*KPI_Weights!$B$6,X18*KPI_Weights!$B$7,Y18*KPI_Weights!$B$8,Z18*KPI_Weights!$B$9,AA18*KPI_Weights!$B$10,AB18*KPI_Weights!$B$11,AC18*KPI_Weights!$B$12,AD18*KPI_Weights!$B$13,AE18*KPI_Weights!$B$14,AF18*KPI_Weights!$B$15,AG18*KPI_Weights!$B$16,AH18*KPI_Weights!$B$17,AI18*KPI_Weights!$B$18))/5) -> 0.698 | AM18: =IF(COUNTA(U18:AI18)=0,"",IF(OR(U18<=1,X18<=1,Y18<=1,Z18<=1,AC18<=1),"YES","NO")) -> NO | AN18: =IF(AK18="","",IF(AND(AM18="NO",AK18>=0.75),"YES","NO")) -> NO | AO18: Need improvments | AP18: YES | AQ18: PTW failure | AR18: HSE Management System Implementation • Planning and Control • Inspection, Monitoring, and Compliance | AS18: unsafe blocks observed in walk fixed away from edge | AT18: Enforce strict supervision and permit compliance. Implement proper planning, housekeeping, and waste management systems. Conduct regular inspections, training, and safety awareness programs. | AV18: Construction manager Project Engineer | AW18: 46126 | AX18: Asite Reff provided
A19: SIDP3-BW-KEO-ZZ-ZZ-XX-WR-HS-75 | B19: 46119 | C19: =IF($B19="","",WEEKNUM($B19,2)) -> 15 | E19: =IF($B19="","",TEXT($B19,"yyyy-mm")) -> 2026-04 | F19: 3 | G19: Cluster 6 | H19: =IF(OR($F19="",$G19=""),"",IFERROR(IF($F19=INDEX(Cluster_Master!$A$4:$A$18,MATCH($G19,Cluster_Master!$B$4:$B$18,0)),"OK","CHECK"),"CHECK")) -> OK | I19: =IFERROR(INDEX(Cluster_Master!$C$4:$C$18,MATCH($G19,Cluster_Master!$B$4:$B$18,0)),"") -> INNOVO | J19: =IFERROR(INDEX(Cluster_Master!$D$4:$D$18,MATCH($G19,Cluster_Master!$B$4:$B$18,0)),"") -> Kahtan Tikriti | K19: =IFERROR(INDEX(Cluster_Master!$E$4:$E$18,MATCH($G19,Cluster_Master!$B$4:$B$18,0)),"") -> Michael Ghali | L19: =IFERROR(INDEX(Cluster_Master!$F$4:$F$18,MATCH($G19,Cluster_Master!$B$4:$B$18,0)),"") -> Remon Karas | M19: =IFERROR(INDEX(Cluster_Master!$G$4:$G$18,MATCH($G19,Cluster_Master!$B$4:$B$18,0)),"") -> Mazen Al Atwani | N19: =IFERROR(INDEX(Cluster_Master!$H$4:$H$18,MATCH($G19,Cluster_Master!$B$4:$B$18,0)),"") -> 0 | O19: Shakir | P19: KEO | Q19: General | S19: Electrical Safety | T19: NO | U19: 4 | V19: 4 | W19: 3 | X19: 3 | Y19: 4 | Z19: 4 | AA19: 3 | AB19: 3 | AC19: 4 | AD19: 3 | AE19: 4 | AF19: 4 | AG19: 3 | AH19: 4 | AI19: 2 | AJ19: =IF(COUNTA(U19:AI19)=0,"",SUM(U19:AI19)) -> 52 | AK19: =IF(COUNTA(U19:AI19)=0,"",AJ19/75) -> 0.69333333 | AL19: =IF(COUNTA(U19:AI19)=0,"",(SUM(U19*KPI_Weights!$B$4,V19*KPI_Weights!$B$5,W19*KPI_Weights!$B$6,X19*KPI_Weights!$B$7,Y19*KPI_Weights!$B$8,Z19*KPI_Weights!$B$9,AA19*KPI_Weights!$B$10,AB19*KPI_Weights!$B$11,AC19*KPI_Weights!$B$12,AD19*KPI_Weights!$B$13,AE19*KPI_Weights!$B$14,AF19*KPI_Weights!$B$15,AG19*KPI_Weights!$B$16,AH19*KPI_Weights!$B$17,AI19*KPI_Weights!$B$18))/5) -> 0.71 | AM19: =IF(COUNTA(U19:AI19)=0,"",IF(OR(U19<=1,X19<=1,Y19<=1,Z19<=1,AC19<=1),"YES","NO")) -> NO | AN19: =IF(AK19="","",IF(AND(AM19="NO",AK19>=0.75),"YES","NO")) -> NO | AO19: =IF(AK19="","",IF(AK19<0.4,"Critical",IF(AK19<0.6,"Poor",IF(AK19<0.75,"Needs Improvement",IF(AK19<0.9,"Good","Excellent"))))) -> Needs Improvement | AP19: YES | AQ19: Poor subcontractor control | AR19: •HSE Management System Implementation • Planning and Control • Inspection, Monitoring, and Compliance | AS19: permit to work verification done on site.edge protection team was called to fix the edge protection and excavation barricades | AT19: Enforce strict supervision and permit compliance. Implement proper planning, housekeeping, and waste management systems. Conduct regular inspections, training, and safety awareness programs. | AV19: Construction Manager | AW19: 46126 | AX19: Asite Reff provided
A20: SIDPW-BW-KEO-ZZ-ZZ-XX-RP-HS-00201 | B20: 46119 | C20: =IF($B20="","",WEEKNUM($B20,2)) -> 15 | E20: =IF($B20="","",TEXT($B20,"yyyy-mm")) -> 2026-04 | F20: 2 | G20: Cluster 7A | H20: =IF(OR($F20="",$G20=""),"",IFERROR(IF($F20=INDEX(Cluster_Master!$A$4:$A$18,MATCH($G20,Cluster_Master!$B$4:$B$18,0)),"OK","CHECK"),"CHECK")) -> OK | I20: =IFERROR(INDEX(Cluster_Master!$C$4:$C$18,MATCH($G20,Cluster_Master!$B$4:$B$18,0)),"") -> TAJV | J20: =IFERROR(INDEX(Cluster_Master!$D$4:$D$18,MATCH($G20,Cluster_Master!$B$4:$B$18,0)),"") -> Hicham Adel Narch | K20: =IFERROR(INDEX(Cluster_Master!$E$4:$E$18,MATCH($G20,Cluster_Master!$B$4:$B$18,0)),"") -> Ghaidh Alfaour | L20: =IFERROR(INDEX(Cluster_Master!$F$4:$F$18,MATCH($G20,Cluster_Master!$B$4:$B$18,0)),"") -> George Deeb | M20: =IFERROR(INDEX(Cluster_Master!$G$4:$G$18,MATCH($G20,Cluster_Master!$B$4:$B$18,0)),"") -> Timur | N20: =IFERROR(INDEX(Cluster_Master!$H$4:$H$18,MATCH($G20,Cluster_Master!$B$4:$B$18,0)),"") -> Liqat | O20: Jackson | P20: KEO | Q20: General | S20: Falling Objects | T20: NO | U20: 3.5 | V20: 3.5 | W20: 3.5 | X20: 2 | Y20: 3 | Z20: 2.5 | AA20: 2.5 | AB20: 4 | AC20: 3 | AD20: 4 | AE20: 3 | AF20: 4 | AG20: 3 | AH20: 3 | AI20: 4 | AJ20: =IF(COUNTA(U20:AI20)=0,"",SUM(U20:AI20)) -> 48.5 | AK20: =IF(COUNTA(U20:AI20)=0,"",AJ20/75) -> 0.64666667 | AL20: =IF(COUNTA(U20:AI20)=0,"",(SUM(U20*KPI_Weights!$B$4,V20*KPI_Weights!$B$5,W20*KPI_Weights!$B$6,X20*KPI_Weights!$B$7,Y20*KPI_Weights!$B$8,Z20*KPI_Weights!$B$9,AA20*KPI_Weights!$B$10,AB20*KPI_Weights!$B$11,AC20*KPI_Weights!$B$12,AD20*KPI_Weights!$B$13,AE20*KPI_Weights!$B$14,AF20*KPI_Weights!$B$15,AG20*KPI_Weights!$B$16,AH20*KPI_Weights!$B$17,AI20*KPI_Weights!$B$18))/5) -> 0.635 | AM20: =IF(COUNTA(U20:AI20)=0,"",IF(OR(U20<=1,X20<=1,Y20<=1,Z20<=1,AC20<=1),"YES","NO")) -> NO | AN20: =IF(AK20="","",IF(AND(AM20="NO",AK20>=0.75),"YES","NO")) -> NO | AO20: =IF(AK20="","",IF(AK20<0.4,"Critical",IF(AK20<0.6,"Poor",IF(AK20<0.75,"Needs Improvement",IF(AK20<0.9,"Good","Excellent"))))) -> Needs Improvement | AP20: YES | AQ20: Poor supervision | AR20: HSE Management System Implementation • Planning and Control • Inspection, Monitoring, and Compliance | AS20: edge protection team was called to fix the edge protection and excavation barricades | AT20: Enforce strict supervision and permit compliance. Implement proper planning, housekeeping, and waste management systems. Conduct regular inspections, training, and safety awareness programs | AV20: Construction manager Project Engineer | AW20: 46124 | AX20: Asite Reff provided
A21: SIDPW-BW-KEO-ZZ-ZZ-XX-RP-HS-00202 | B21: 46119 | C21: =IF($B21="","",WEEKNUM($B21,2)) -> 15 | E21: =IF($B21="","",TEXT($B21,"yyyy-mm")) -> 2026-04 | F21: 2 | G21: Cluster 7A | H21: =IF(OR($F21="",$G21=""),"",IFERROR(IF($F21=INDEX(Cluster_Master!$A$4:$A$18,MATCH($G21,Cluster_Master!$B$4:$B$18,0)),"OK","CHECK"),"CHECK")) -> OK | I21: =IFERROR(INDEX(Cluster_Master!$C$4:$C$18,MATCH($G21,Cluster_Master!$B$4:$B$18,0)),"") -> TAJV | J21: =IFERROR(INDEX(Cluster_Master!$D$4:$D$18,MATCH($G21,Cluster_Master!$B$4:$B$18,0)),"") -> Hicham Adel Narch | K21: =IFERROR(INDEX(Cluster_Master!$E$4:$E$18,MATCH($G21,Cluster_Master!$B$4:$B$18,0)),"") -> Ghaidh Alfaour | L21: =IFERROR(INDEX(Cluster_Master!$F$4:$F$18,MATCH($G21,Cluster_Master!$B$4:$B$18,0)),"") -> George Deeb | M21: =IFERROR(INDEX(Cluster_Master!$G$4:$G$18,MATCH($G21,Cluster_Master!$B$4:$B$18,0)),"") -> Timur | N21: =IFERROR(INDEX(Cluster_Master!$H$4:$H$18,MATCH($G21,Cluster_Master!$B$4:$B$18,0)),"") -> Liqat | O21: Jackson | P21: KEO | Q21: General | S21: Edge Protection | T21: NO | U21: 4 | V21: 3.5 | W21: 4 | X21: 4 | Y21: 3.5 | Z21: 4 | AA21: 4 | AB21: 4 | AC21: 4 | AD21: 4 | AE21: 4 | AF21: 4 | AG21: 3 | AH21: 4 | AI21: 4 | AJ21: =IF(COUNTA(U21:AI21)=0,"",SUM(U21:AI21)) -> 58 | AK21: =IF(COUNTA(U21:AI21)=0,"",AJ21/75) -> 0.77333333 | AL21: =IF(COUNTA(U21:AI21)=0,"",(SUM(U21*KPI_Weights!$B$4,V21*KPI_Weights!$B$5,W21*KPI_Weights!$B$6,X21*KPI_Weights!$B$7,Y21*KPI_Weights!$B$8,Z21*KPI_Weights!$B$9,AA21*KPI_Weights!$B$10,AB21*KPI_Weights!$B$11,AC21*KPI_Weights!$B$12,AD21*KPI_Weights!$B$13,AE21*KPI_Weights!$B$14,AF21*KPI_Weights!$B$15,AG21*KPI_Weights!$B$16,AH21*KPI_Weights!$B$17,AI21*KPI_Weights!$B$18))/5) -> 0.768 | AM21: =IF(COUNTA(U21:AI21)=0,"",IF(OR(U21<=1,X21<=1,Y21<=1,Z21<=1,AC21<=1),"YES","NO")) -> NO | AN21: =IF(AK21="","",IF(AND(AM21="NO",AK21>=0.75),"YES","NO")) -> YES | AO21: =IF(AK21="","",IF(AK21<0.4,"Critical",IF(AK21<0.6,"Poor",IF(AK21<0.75,"Needs Improvement",IF(AK21<0.9,"Good","Excellent"))))) -> Good | AP21: YES | AQ21: Poor supervision | AR21: •HSE Management System Implementation • Planning and Control • Inspection, Monitoring, and Compliance | AS21: Instructed contractor to reverify all scaffolding | AT21: Competent scaffolding inspector shall be inspected all scaffolding units | AV21: Construction manager Project Engineer | AW21: 46124 | AX21: Asite Reff provided
A22: SIDP3-BW-KEO-ZZ-ZZ-XX-RP-HS-00164 | B22: 46120 | C22: =IF($B22="","",WEEKNUM($B22,2)) -> 15 | E22: =IF($B22="","",TEXT($B22,"yyyy-mm")) -> 2026-04 | F22: 3 | G22: Cluster 6 | H22: =IF(OR($F22="",$G22=""),"",IFERROR(IF($F22=INDEX(Cluster_Master!$A$4:$A$18,MATCH($G22,Cluster_Master!$B$4:$B$18,0)),"OK","CHECK"),"CHECK")) -> OK | I22: =IFERROR(INDEX(Cluster_Master!$C$4:$C$18,MATCH($G22,Cluster_Master!$B$4:$B$18,0)),"") -> INNOVO | J22: =IFERROR(INDEX(Cluster_Master!$D$4:$D$18,MATCH($G22,Cluster_Master!$B$4:$B$18,0)),"") -> Kahtan Tikriti | K22: =IFERROR(INDEX(Cluster_Master!$E$4:$E$18,MATCH($G22,Cluster_Master!$B$4:$B$18,0)),"") -> Michael Ghali | L22: =IFERROR(INDEX(Cluster_Master!$F$4:$F$18,MATCH($G22,Cluster_Master!$B$4:$B$18,0)),"") -> Remon Karas | M22: =IFERROR(INDEX(Cluster_Master!$G$4:$G$18,MATCH($G22,Cluster_Master!$B$4:$B$18,0)),"") -> Mazen Al Atwani | N22: =IFERROR(INDEX(Cluster_Master!$H$4:$H$18,MATCH($G22,Cluster_Master!$B$4:$B$18,0)),"") -> 0 | O22: Shakir | P22: KEO | Q22: General | S22: Excavation | T22: YES | U22: 4 | V22: 2 | W22: 4 | X22: 4 | Y22: 4 | Z22: 3 | AA22: 3 | AB22: 4 | AD22: 3 | AE22: 3 | AF22: 4 | AG22: 4 | AH22: 4 | AI22: 3 | AJ22: =IF(COUNTA(U22:AI22)=0,"",SUM(U22:AI22)) -> 49 | AK22: =IF(COUNTA(U22:AI22)=0,"",AJ22/75) -> 0.65333333 | AL22: =IF(COUNTA(U22:AI22)=0,"",(SUM(U22*KPI_Weights!$B$4,V22*KPI_Weights!$B$5,W22*KPI_Weights!$B$6,X22*KPI_Weights!$B$7,Y22*KPI_Weights!$B$8,Z22*KPI_Weights!$B$9,AA22*KPI_Weights!$B$10,AB22*KPI_Weights!$B$11,AC22*KPI_Weights!$B$12,AD22*KPI_Weights!$B$13,AE22*KPI_Weights!$B$14,AF22*KPI_Weights!$B$15,AG22*KPI_Weights!$B$16,AH22*KPI_Weights!$B$17,AI22*KPI_Weights!$B$18))/5) -> 0.614 | AM22: =IF(COUNTA(U22:AI22)=0,"",IF(OR(U22<=1,X22<=1,Y22<=1,Z22<=1,AC22<=1),"YES","NO")) -> YES | AN22: =IF(AK22="","",IF(AND(AM22="NO",AK22>=0.75),"YES","NO")) -> NO | AO22: =IF(AK22="","",IF(AK22<0.4,"Critical",IF(AK22<0.6,"Poor",IF(AK22<0.75,"Needs Improvement",IF(AK22<0.9,"Good","Excellent"))))) -> Needs Improvement | AP22: YES | AQ22: Poor supervision | AR22: HSE Management System Implementation • Planning and Control • Inspection, Monitoring, and Compliance | AS22: Worker removed from the villa in adequate access and edge protection | AT22: • Enforce strict supervision and permit compliance. • Implement proper planning, housekeeping, and waste management systems. • Conduct regular inspections, training, and safety awareness programs. • Access should always be well-maintained and inspected by a competent person • Permit to work should only be issued if the villa is safe to work in | AV22: Construction manager Project Engineer | AW22: 46127 | AX22: Asite Reff provided
A23: SIDP3-BW-KEO-ZZ-ZZ-XX-RP-HS-00163 | B23: 46120 | C23: =IF($B23="","",WEEKNUM($B23,2)) -> 15 | E23: =IF($B23="","",TEXT($B23,"yyyy-mm")) -> 2026-04 | F23: 3 | G23: Cluster 3 | H23: =IF(OR($F23="",$G23=""),"",IFERROR(IF($F23=INDEX(Cluster_Master!$A$4:$A$18,MATCH($G23,Cluster_Master!$B$4:$B$18,0)),"OK","CHECK"),"CHECK")) -> OK | I23: =IFERROR(INDEX(Cluster_Master!$C$4:$C$18,MATCH($G23,Cluster_Master!$B$4:$B$18,0)),"") -> INNOVO | J23: =IFERROR(INDEX(Cluster_Master!$D$4:$D$18,MATCH($G23,Cluster_Master!$B$4:$B$18,0)),"") -> Kahtan Tikriti | K23: =IFERROR(INDEX(Cluster_Master!$E$4:$E$18,MATCH($G23,Cluster_Master!$B$4:$B$18,0)),"") -> Aiman Abdullah | L23: =IFERROR(INDEX(Cluster_Master!$F$4:$F$18,MATCH($G23,Cluster_Master!$B$4:$B$18,0)),"") -> Salama Al Samdy | M23: =IFERROR(INDEX(Cluster_Master!$G$4:$G$18,MATCH($G23,Cluster_Master!$B$4:$B$18,0)),"") -> Mazen Al Atwani | N23: =IFERROR(INDEX(Cluster_Master!$H$4:$H$18,MATCH($G23,Cluster_Master!$B$4:$B$18,0)),"") -> 0 | O23: Shinoj M | P23: KEO | Q23: Block 03 | S23: Permit to Work | T23: YES | U23: 2 | V23: 4 | W23: 4 | X23: 3 | Y23: 3 | Z23: 1 | AA23: 1 | AB23: 3 | AC23: 3 | AD23: 2 | AE23: 2 | AF23: 4 | AG23: 4 | AH23: 2 | AI23: 2 | AJ23: =IF(COUNTA(U23:AI23)=0,"",SUM(U23:AI23)) -> 40 | AK23: =IF(COUNTA(U23:AI23)=0,"",AJ23/75) -> 0.53333333 | AL23: =IF(COUNTA(U23:AI23)=0,"",(SUM(U23*KPI_Weights!$B$4,V23*KPI_Weights!$B$5,W23*KPI_Weights!$B$6,X23*KPI_Weights!$B$7,Y23*KPI_Weights!$B$8,Z23*KPI_Weights!$B$9,AA23*KPI_Weights!$B$10,AB23*KPI_Weights!$B$11,AC23*KPI_Weights!$B$12,AD23*KPI_Weights!$B$13,AE23*KPI_Weights!$B$14,AF23*KPI_Weights!$B$15,AG23*KPI_Weights!$B$16,AH23*KPI_Weights!$B$17,AI23*KPI_Weights!$B$18))/5) -> 0.534 | AM23: =IF(COUNTA(U23:AI23)=0,"",IF(OR(U23<=1,X23<=1,Y23<=1,Z23<=1,AC23<=1),"YES","NO")) -> YES | AN23: =IF(AK23="","",IF(AND(AM23="NO",AK23>=0.75),"YES","NO")) -> NO | AO23: =IF(AK23="","",IF(AK23<0.4,"Critical",IF(AK23<0.6,"Poor",IF(AK23<0.75,"Needs Improvement",IF(AK23<0.9,"Good","Excellent"))))) -> Poor | AP23: YES | AQ23: Poor subcontractor control | AR23: 1. Communication of OHS procedures 2. lack of OHS awareness in supervision level 3. Lack of monitoring | AS23: 1. Worker removed from the villa 2. safe access provided by the contractor 3. allocated people fro material arrangements | AT23: 1. Conduct training and awareness on the site supervision level 2. Conduct routine inspections 3. | AV23: 1. Project engineer 2. Construction Manager 3. OHS offcer | AX23: Asite Reff provided
A24: SIDP3-BW-KEO-ZZ-ZZ-XX-RP-HS-00165 | B24: 46122 | C24: =IF($B24="","",WEEKNUM($B24,2)) -> 15 | E24: =IF($B24="","",TEXT($B24,"yyyy-mm")) -> 2026-04 | F24: 3 | G24: Cluster 4 | H24: =IF(OR($F24="",$G24=""),"",IFERROR(IF($F24=INDEX(Cluster_Master!$A$4:$A$18,MATCH($G24,Cluster_Master!$B$4:$B$18,0)),"OK","CHECK"),"CHECK")) -> OK | I24: =IFERROR(INDEX(Cluster_Master!$C$4:$C$18,MATCH($G24,Cluster_Master!$B$4:$B$18,0)),"") -> INNOVO | J24: =IFERROR(INDEX(Cluster_Master!$D$4:$D$18,MATCH($G24,Cluster_Master!$B$4:$B$18,0)),"") -> Kahtan Tikriti | K24: =IFERROR(INDEX(Cluster_Master!$E$4:$E$18,MATCH($G24,Cluster_Master!$B$4:$B$18,0)),"") -> Aiman Abdullah | L24: =IFERROR(INDEX(Cluster_Master!$F$4:$F$18,MATCH($G24,Cluster_Master!$B$4:$B$18,0)),"") -> Baha Basheer | M24: =IFERROR(INDEX(Cluster_Master!$G$4:$G$18,MATCH($G24,Cluster_Master!$B$4:$B$18,0)),"") -> Mazen Al Atwani | N24: =IFERROR(INDEX(Cluster_Master!$H$4:$H$18,MATCH($G24,Cluster_Master!$B$4:$B$18,0)),"") -> 0 | O24: Shinoj M | P24: KEO | Q24: Block 02 &01 | S24: Edge Protection | T24: NO | U24: 4 | V24: 3 | W24: 4 | X24: 3 | Y24: 4 | Z24: 3 | AA24: 4 | AB24: 4 | AC24: 4 | AD24: 3 | AE24: 4 | AF24: 4 | AG24: 3 | AH24: 4 | AI24: 3 | AJ24: =IF(COUNTA(U24:AI24)=0,"",SUM(U24:AI24)) -> 54 | AK24: =IF(COUNTA(U24:AI24)=0,"",AJ24/75) -> 0.72 | AL24: =IF(COUNTA(U24:AI24)=0,"",(SUM(U24*KPI_Weights!$B$4,V24*KPI_Weights!$B$5,W24*KPI_Weights!$B$6,X24*KPI_Weights!$B$7,Y24*KPI_Weights!$B$8,Z24*KPI_Weights!$B$9,AA24*KPI_Weights!$B$10,AB24*KPI_Weights!$B$11,AC24*KPI_Weights!$B$12,AD24*KPI_Weights!$B$13,AE24*KPI_Weights!$B$14,AF24*KPI_Weights!$B$15,AG24*KPI_Weights!$B$16,AH24*KPI_Weights!$B$17,AI24*KPI_Weights!$B$18))/5) -> 0.71 | AM24: =IF(COUNTA(U24:AI24)=0,"",IF(OR(U24<=1,X24<=1,Y24<=1,Z24<=1,AC24<=1),"YES","NO")) -> NO | AN24: =IF(AK24="","",IF(AND(AM24="NO",AK24>=0.75),"YES","NO")) -> NO | AO24: =IF(AK24="","",IF(AK24<0.4,"Critical",IF(AK24<0.6,"Poor",IF(AK24<0.75,"Needs Improvement",IF(AK24<0.9,"Good","Excellent"))))) -> Needs Improvement | AP24: YES | AQ24: Inadequate competence | AR24: 1. Training and awareness 2. Supervision 3. Inspection | AS24: 1. Appoint a competent team for barricading arrangements 2. Provide rebar caps fro protruding steel 3. Provide our riggers for scaffolding | AT24: 1. Competency assessment should be conducted 2. Period monitoring should be implemented 3. Preventive maintenance should be conducted | AV24: 1 Construction Manager 2 Project Engineer 3 HSE | AX24: Asite Reff provided
